<?xml version="1.0" ?>
<!-- =================================================================================== -->
<!-- |    This document was autogenerated by xacro from robot_arm.xacro                | -->
<!-- |    EDITING THIS FILE BY HAND IS NOT RECOMMENDED                                 | -->
<!-- =================================================================================== -->
<robot name="seven_dof_arm">
  <property name="deg_to_rad" value="0.01745329251994329577"/>
  <!-- Constants -->
  <property name="M_SCALE" value="0.001 0.001 0.001"/>
  <property name="M_PI" value="3.14159"/>
  <!-- Shoulder pan link properties -->
  <property name="shoulder_pan_width" value="0.04"/>
  <property name="shoulder_pan_len" value="0.08"/>
  <!-- Shoulder pitch link properties -->
  <property name="shoulder_pitch_len" value="0.14"/>
  <property name="shoulder_pitch_width" value="0.04"/>
  <property name="shoulder_pitch_height" value="0.04"/>
  <!-- Elbow roll link properties -->
  <property name="elbow_roll_width" value="0.02"/>
  <property name="elbow_roll_len" value="0.06"/>
  <!-- Elbow pitch link properties -->
  <property name="elbow_pitch_len" value="0.22"/>
  <property name="elbow_pitch_width" value="0.04"/>
  <property name="elbow_pitch_height" value="0.04"/>
  <!-- Wrist roll link properties -->
  <property name="wrist_roll_width" value="0.02"/>
  <property name="wrist_roll_len" value="0.04"/>
  <!-- wrist pitch link properties -->
  <property name="wrist_pitch_len" value="0.06"/>
  <property name="wrist_pitch_width" value="0.04"/>
  <property name="wrist_pitch_height" value="0.04"/>
  <!-- Gripper roll link properties -->
  <property name="gripper_roll_width" value="0.04"/>
  <property name="gripper_roll_len" value="0.02"/>
  <!-- Left gripper -->
  <property name="left_gripper_len" value="0.08"/>
  <property name="left_gripper_width" value="0.01"/>
  <property name="left_gripper_height" value="0.01"/>
  <!-- Right gripper -->
  <property name="right_gripper_len" value="0.08"/>
  <property name="right_gripper_width" value="0.01"/>
  <property name="right_gripper_height" value="0.01"/>
  <!-- Right gripper -->
  <property name="grasp_frame_len" value="0.02"/>
  <property name="grasp_frame_width" value="0.02"/>
  <property name="grasp_frame_height" value="0.02"/>
  <!-- Materials -->
  <material name="Black">
    <color rgba="0.0 0.0 0.0 1.0"/>
  </material>
  <material name="Red">
    <color rgba="1.0 0.0 0.0 1.0"/>
  </material>
  <material name="White">
    <color rgba="1.0 1.0 1.0 1.0"/>
  </material>
  <link name="bottom_link">
    <visual>
      <origin rpy="0 0 0" xyz="0 0 0"/>
      <geometry>
        <box size="1 1 0.02"/>
      </geometry>
      <material name="Black"/>
    </visual>
    <collision>
      <origin rpy="0 0 0" xyz="0 0 0"/>
      <geometry>
        <box size="1 1 0.02"/>
      </geometry>
    </collision>
  </link>
  <joint name="bottom_joint" type="fixed">
    <origin rpy="0 0 0" xyz="0 0 0"/>
    <parent link="base_link"/>
    <child link="bottom_link"/>
  </joint>
  <link name="base_link">
    <visual>
      <origin rpy="0 0 0" xyz="0 0 0"/>
      <geometry>
        <box size="0.1 0.1 0.1"/>
      </geometry>
      <material name="White"/>
    </visual>
    <collision>
      <origin rpy="0 0 0" xyz="0 0 0"/>
      <geometry>
        <box size="0.1 0.1 0.1"/>
      </geometry>
    </collision>
    <inertial>
      <mass value="1"/>
      <inertia ixx="1.0" ixy="0.0" ixz="0.0" iyy="0.5" iyz="0.0" izz="1.0"/>
    </inertial>
  </link>
  <joint name="shoulder_pan_joint" type="revolute">
    <origin rpy="0 0 0" xyz="0 0 0"/>
    <parent link="base_link"/>
    <child link="shoulder_pan_link"/>
    <limit effort="300" lower="-2.61799387799" upper="1.98394848567" velocity="1"/>
    <dynamics damping="50" friction="1"/>
  </joint>
  <link name="shoulder_pan_link">
    <visual>
      <origin rpy="0 0 0" xyz="0 0 0"/>
      <geometry>
        <cylinder length="0.04" radius="0.04"/>
      </geometry>
      <material name="Red"/>
    </visual>
    <collision>
      <origin rpy="0 0 0" xyz="0 0 0"/>
      <geometry>
        <cylinder length="0.04" radius="0.04"/>
      </geometry>
    </collision>
    <inertial>
      <mass value="1"/>
      <inertia ixx="1.0" ixy="0.0" ixz="0.0" iyy="0.5" iyz="0.0" izz="1.0"/>
    </inertial>
  </link>
  <!-- <joint name="shoulder_pitch_joint" type="revolute">
  <origin xyz="0 0 0" rpy="0 0 0"/>
  <parent link="shoulder_pan_link"/>
  <child link="shoulder_pitch_link"/>
</joint>

<joint name="elbow_roll_joint" type="revolute">
  <origin xyz="0 0 0" rpy="0 0 0"/>
  <parent link="shoulder_pitch_link"/>
  <child link="elbow_roll_link"/>
</joint>

<joint name="elbow_pitch_joint" type="revolute">
  <origin xyz="0 0 0" rpy="0 0 0"/>
  <parent link="elbow_roll_link"/>
  <child link="elbow_pitch_link"/>
</joint>

<joint name="wrist_roll_joint" type="revolute">
  <origin xyz="0 0 0" rpy="0 0 0"/>
  <parent link="elbow_pitch_link"/>
  <child link="wrist_roll_link"/>
</joint>

<joint name="wrist_pitch_joint" type="revolute">
  <origin xyz="0 0 0" rpy="0 0 0"/>
  <parent link="wrist_roll_link"/>
  <child link="wrist_pitch_link"/>
</joint>

<joint name="gripper_roll_joint" type="revolute">
  <origin xyz="0 0 0" rpy="0 0 0"/>
  <parent link="wrist_pitch_link"/>
  <child link="gripper_roll_link"/>
</joint>

<joint name="finger_joint1" type="prismatic">
  <origin xyz="0 0 0" rpy="0 0 0"/>
  <parent link="gripper_roll_link"/>
  <child link="gripper_finger_link1"/>
</joint>

<joint name="finger_joint2" type="prismatic">
  <origin xyz="0 0 0" rpy="0 0 0"/>
  <parent link="gripper_roll_link"/>
  <child link="gripper_finger_link2"/>
</joint> -->
</robot>

