<?xml version="1.0"?>

<robot name="seven_dof_arm" xmlns:xacro="http://www.ros.org/wiki/xacro">

<!-- Materials -->

<material name="Black">
  <color rgba="0.0 0.0 0.0 1.0"/>
</material>

<material name="Red">
  <color rgba="1.0 0.0 0.0 1.0"/>
</material>

<material name="White">
  <color rgba="1.0 1.0 1.0 1.0"/>
</material>



<xacro:macro name="inertial_matrix" params="mass">  
    <inertial>
        <mass value="${mass}"/>
        <inertia ixx="1.0" ixy="0.0" ixz="0.0" iyy="0.5" iyz="0.0" izz="1.0"/>
    </inertial>
</xacro:macro>

<link name="world"/>

<joint name="fix_world" type="fixed">
  <parent link="world"/>
  <child link="base_link"/>
  <origin xyz="0 0 0" rpy="0 0 0"/>
</joint>


<link name="base_link">
  <visual>
    <origin xyz="0 0 0" rpy="0 0 0"/>
    <geometry>
      <box size="0.1 0.1 0.1"/>
    </geometry>
    <material name="White"/>
  </visual>
  <collision>
    <origin xyz="0 0 0.05" rpy="0 0 0"/>
    <geometry>
      <box size="0.1 0.1 0.1"/>
    </geometry>
  </collision>
  <xacro:inertial_matrix mass="1"/>
</link>


<joint name="shoulder_pan_joint" type="revolute">
  <origin xyz="0 0 0.05" rpy="0 0 0"/>
  <axis xyz="0 0 1"/>
  <parent link="base_link"/>
  <child link="shoulder_pan_link"/>
  <limit effort="300" velocity="0.5" lower="-3.14" upper="3.14"/>
  <dynamics damping="50" friction="1"/>
</joint>


<link name="shoulder_pan_link">
  <visual>
    <origin xyz="0 0 0.02" rpy="0 0 0"/>
    <geometry>
      <cylinder radius="0.04" length="0.04"/>
    </geometry> 
    <material name="Red"/>
  </visual>
  <collision>
    <origin xyz="0 0 0.02" rpy="0 0 0"/>
    <geometry>
      <cylinder radius="0.04" length="0.04"/>
    </geometry>
  </collision>
  <xacro:inertial_matrix mass="1"/>
</link>


<joint name="shoulder_pitch_joint" type="revolute">
  <parent link="shoulder_pan_link"/>
  <child link="shoulder_pitch_link"/>
  <origin xyz="-0.04 0.0 0.04" rpy="0 0 -${3.14/2}" />
  <axis xyz="1 0 0" />
  <limit effort="300" velocity="0.5" lower="0" upper="1.89994105047" />
  <dynamics damping="50" friction="1"/>
</joint>


<link name="shoulder_pitch_link">
  <visual>
    <origin xyz="-0.002 0 0.07" rpy="0 ${3.14/2} 0"/>
    <geometry>
      <box size="0.14 0.04 0.04"/>
    </geometry>
    <material name="White"/>
  </visual>
  <collision>
    <origin xyz="-0.002 0 0.07" rpy="0 ${3.14/2} 0"/>
    <geometry>
      <box size="0.14 0.04 0.04"/>
    </geometry>
  </collision>
  <xacro:inertial_matrix mass="1"/>
</link>


<joint name="elbow_roll_joint" type="revolute">
  <parent link="shoulder_pitch_link"/>
  <child link="elbow_roll_link"/>
  <origin xyz="0.0 0 0.14" rpy="${3.14} ${3.14/2} 0" />
  <axis xyz="-1 0 0" />
  <limit effort="300" velocity="0.5" lower="-3.14" upper="3.14" />
  <dynamics damping="50" friction="1"/>
</joint>


<link name="elbow_roll_link">
  <visual>
    <origin xyz="-0.03 0 0.0" rpy="0 ${3.14/2} 0"/>
    <geometry>
      <cylinder radius="0.02" length="0.06"/>
    </geometry>
    <material name="Black"/>
  </visual>
  <collision>
    <origin xyz="-0.03 0 0.0" rpy="0 ${3.14/2} 0"/>
    <geometry>
      <cylinder radius="0.02" length="0.06"/>
    </geometry>
  </collision>
  <xacro:inertial_matrix mass="1"/>
</link>


<joint name="elbow_pitch_joint" type="revolute">
  <parent link="elbow_roll_link"/>
  <child link="elbow_pitch_link"/>
  <origin xyz="-0.06 0 0" rpy="0 ${3.14/2} 0" />
  <axis xyz="1 0 0" />
  <limit effort="300" velocity="0.5" lower="0" upper="1.5" />
  <dynamics damping="50" friction="1"/>
</joint>


<link name="elbow_pitch_link">
  <visual>
    <origin xyz="0.0 0 -0.11" rpy="0 ${3.14/2} 0"/>
    <geometry>
      <box size="0.22 0.04 0.04"/>
    </geometry>
    <material name="Red"/>
  </visual>
  <collision>
    <origin xyz="0.0 0 -0.11" rpy="0 ${3.14/2} 0"/>
    <geometry>
      <box size="0.22 0.04 0.04"/>
    </geometry>
  </collision>
  <xacro:inertial_matrix mass="1"/>
</link>


<joint name="wrist_roll_joint" type="revolute">
  <parent link="elbow_pitch_link"/>
  <child link="wrist_roll_link"/>
  <origin xyz="0.0 0.0 -0.22" rpy="0 0 0" />
  <axis xyz="1 0 0" />
  <limit effort="300" velocity="0.5" lower="-1.57" upper="1.57" />
  <dynamics damping="50" friction="1"/>
</joint>


<link name="wrist_roll_link">
  <visual>
    <origin xyz="0.0 0.0 -0.02" rpy="0 ${3.14/2} 0"/>
    <geometry>
      <cylinder radius="0.02" length="0.04"/>
    </geometry>
    <material name="Black"/>
  </visual>
  <collision>
    <origin xyz="-0.02 0 0.00" rpy="0 ${3.14/2} 0"/>
    <geometry>
      <cylinder radius="0.02" length="0.04"/>
    </geometry>
  </collision>
  <xacro:inertial_matrix mass="1"/>
</link>



<joint name="wrist_pitch_joint" type="revolute">
  <parent link="wrist_roll_link"/>
  <child link="wrist_pitch_link"/>
  <origin xyz="0.0 0.0 -0.04" rpy="0 0 0" />
  <axis xyz="1 0 0" />
  <limit effort="300" velocity="0.5" lower="-1.5" upper="1.5" />
  <dynamics damping="50" friction="1"/>
</joint>


<link name="wrist_pitch_link">
  <visual>
    <origin xyz="0.0 0.0 -0.03" rpy="0 ${3.14/2} 0"/>
    <geometry>
      <box size="0.06 0.04 0.04"/>
    </geometry>
    <material name="White"/>
  </visual>
  <collision>
    <origin xyz="0 0 -0.03" rpy="0 ${3.14/2} 0"/>
    <geometry>
      <box size="0.06 0.04 0.04"/>
    </geometry>
  </collision>
  <xacro:inertial_matrix mass="1"/>
</link>


<joint name="gripper_roll_joint" type="revolute">
  <parent link="wrist_pitch_link"/>
  <child link="gripper_roll_link"/>
  <origin xyz="0 0 -0.06" rpy="-${1.5*3.14} ${.5*3.14} 0" />
  <axis xyz="1 0 0" />
  <limit effort="300" velocity="0.5" lower="-2.61799387799" upper="2.6128806087" />
  <dynamics damping="50" friction="1"/>
</joint>


<link name="gripper_roll_link">
  <visual>
    <origin xyz="0 0 0.0" rpy="0 -${3.14/2} 0"/>
    <geometry>
      <cylinder radius="0.04" length="0.02"/>
    </geometry>
    <material name="Red"/>
  </visual>
  <collision>
    <origin xyz="0 0 0.0" rpy="0 ${3.14/2} 0"/>
    <geometry>
      <cylinder radius="0.04" length="0.02"/>
    </geometry>
  </collision>
  <xacro:inertial_matrix mass="1"/>
</link>


<joint name="finger_joint1" type="prismatic">
  <parent link="gripper_roll_link"/>
  <child link="gripper_finger_link1"/>
  <origin xyz="0.0 0 0" />
  <axis xyz="0 1 0" />
    <limit effort="100" lower="0" upper="0.03" velocity="1.0"/>

    <safety_controller k_position="20"
                       k_velocity="20"
                       soft_lower_limit="${-0.15 }"
                       soft_upper_limit="${ 0.0 }"/>

  <dynamics damping="50" friction="1"/>
</joint>


<link name="gripper_finger_link1">
  <visual>
    <origin xyz="0.04 -0.03 0"/>
    <geometry>
      <box size="0.08 0.01 0.01"/>
    </geometry>
    <material name="White"/>
  </visual>
  <xacro:inertial_matrix mass="1"/>
</link>


<joint name="finger_joint2" type="prismatic">
  <parent link="gripper_roll_link"/>
  <child link="gripper_finger_link2"/>
  <origin xyz="0.0 0 0" />
  <axis xyz="0 1 0" />
  <limit effort="1" lower="-0.03" upper="0" velocity="1.0"/>

  <dynamics damping="50" friction="1"/>
</joint> 


<link name="gripper_finger_link2">
  <visual>
    <origin xyz="0.04 0.03 0"/>
    <geometry>
      <box size="0.08 0.01 0.01"/>
    </geometry>
    <material name="White"/>
  </visual>
  <xacro:inertial_matrix mass="1"/>
</link>


<!-- Transmission block -->
<xacro:macro name="transmission_block" params="joint_name">
	<transmission name="tran1">
	  <type>transmission_interface/SimpleTransmission</type>
	  <joint name="${joint_name}">
	    <hardwareInterface>hardware_interface/PositionJointInterface</hardwareInterface>
	  </joint>
	  <actuator name="motor1">
	    <hardwareInterface>hardware_interface/PositionJointInterface</hardwareInterface>
	    <mechanicalReduction>1</mechanicalReduction>
	  </actuator>
	</transmission>
</xacro:macro>

<!-- Transmissions for ROS Control -->
<xacro:transmission_block joint_name="shoulder_pan_joint"/>
<xacro:transmission_block joint_name="shoulder_pitch_joint"/>
<xacro:transmission_block joint_name="elbow_roll_joint"/>
<xacro:transmission_block joint_name="elbow_pitch_joint"/>
<xacro:transmission_block joint_name="wrist_roll_joint"/>
<xacro:transmission_block joint_name="wrist_pitch_joint"/>
<xacro:transmission_block joint_name="gripper_roll_joint"/>
<xacro:transmission_block joint_name="finger_joint1"/>
<xacro:transmission_block joint_name="finger_joint2"/>



<!-- Colors in gazebo -->

<gazebo reference="base_link">
  <material>Gazebo/White</material>
</gazebo>

<gazebo reference="shoulder_pan_link">
  <material>Gazebo/Red</material>
</gazebo>

<gazebo reference="shoulder_pitch_link">
  <material>Gazebo/White</material>
</gazebo>

<gazebo reference="elbow_roll_link">
  <material>Gazebo/Black</material>
</gazebo>

<gazebo reference="elbow_pitch_link">
  <material>Gazebo/Red</material>
</gazebo>

<gazebo reference="wrist_roll_link">
  <material>Gazebo/Black</material>
</gazebo>

<gazebo reference="wrist_pitch_link">
  <material>Gazebo/White</material>
</gazebo>

<gazebo reference="gripper_roll_link">
  <material>Gazebo/Red</material>
</gazebo>

<gazebo reference="gripper_finger_link1">
  <material>Gazebo/White</material>
</gazebo>

<gazebo reference="gripper_finger_link1">
  <material>Gazebo/White</material>
</gazebo>


<!-- ros_control plugin -->
<gazebo>
  <plugin name="gazebo_ros_control" filename="libgazebo_ros_control.so">
    <robotNamespace>/seven_dof_arm</robotNamespace>
  </plugin>
</gazebo>


</robot>