<?xml version="1.0"?>

<robot name="arm" xmlns:xacro="http://www.ros.org/wiki/xacro">


<!-- Materials -->

<material name="Black">
  <color rgba="0.0 0.0 0.0 1.0"/>
</material>

<material name="Red">
  <color rgba="1.0 0.0 0.0 1.0"/>
</material>

<material name="White">
  <color rgba="1.0 1.0 1.0 1.0"/>
</material>


<link name="base_link">
    <visual>
        <origin rpy="0 0 0" xyz="0 0 0"/>
        <geometry>
            <box size="1 1 1"/>
        </geometry>
        <material name="Black"/>
    </visual>
</link>

<joint name="base_link_link_01" type="revolute">
    <origin rpy="0 0 0" xyz="0 0 0.5"/>
    <parent link="base_link"/>
    <child link="link_01"/>
    <axis xyz="0 0 1"/>
    <limit effort="300" lower="-3.14" upper="3.14" velocity="0.5"/>
</joint>

<link name="link_01">
    <visual>
        <origin rpy="0 0 0" xyz="0 0 0.2"/>
        <geometry>
            <cylinder radius="0.35" length="0.4"/>
        </geometry>
        <material name="Red"/>
    </visual>
    <collision>
        <origin rpy="0 0 0" xyz="0 0 0.2"/>
        <geometry>
            <cylinder radius="0.35" length="0.4"/>
        </geometry>
    </collision>
</link>

<joint name="link_01_link_02" type="revolute">
    <origin rpy="0 0 0" xyz="0 0 0.4"/>
    <parent link="link_01"/>
    <child link="link_02"/>
    <axis xyz="0 1 0"/>
    <limit effort="300" lower="-0.67" upper="0.67" velocity="0.5"/>
</joint>

<link name="link_02">
    <visual>
        <origin rpy="0 0 0" xyz="0 0 0.4"/>
        <geometry>
            <cylinder radius="0.15" length="0.8"/>
        </geometry>
        <material name="White"/>
    </visual>
</link>

<joint name="link_02_link_03" type="revolute">
    <origin rpy="0 0 0" xyz="0 0 0.8"/>
    <parent link="link_02"/>
    <child link="link_03"/>
    <axis xyz="0 1 0"/>
    <limit effort="300" lower="-1.5" upper="1.5" velocity="0.5"/>
</joint>

<link name="link_03">
    <visual>
        <origin rpy="0 0 0" xyz="0 0 0.4"/>
        <geometry>
            <cylinder radius="0.15" length="0.8"/>
        </geometry>
        <material name="Red"/>
    </visual>
    <collision>
        <origin rpy="0 0 0" xyz="0 0 0.4"/>
        <geometry>
            <cylinder radius="0.15" length="0.8"/>
        </geometry>
    </collision>
</link>


<joint name="link_03_link_04" type="revolute">
    <origin rpy="0 0 0" xyz="0 0 0.8"/>
    <parent link="link_03"/>
    <child link="link_04"/>
    <axis xyz="0 1 0"/>
    <limit effort="300" lower="-1.5" upper="1.5" velocity="0.5"/>
</joint>


<link name="link_04">
    <visual>
        <origin rpy="0 0 0" xyz="0 0 0.4"/>
        <geometry>
            <cylinder radius="0.15" length="0.8"/>
        </geometry>
        <material name="Black"/>
    </visual>
    <collision>
        <origin rpy="0 0 0" xyz="0 0 0.4"/>
        <geometry>
            <cylinder radius="0.15" length="0.8"/>
        </geometry>
    </collision>
</link>


<joint name="link_04_link_05" type="revolute">
    <origin rpy="0 0 0" xyz="0 0 0.8"/>
    <parent link="link_04"/>
    <child link="link_05"/>
    <axis xyz="0 1 0"/>
    <limit effort="300" lower="-1.5" upper="1.5" velocity="0.5"/>
</joint>


<link name="link_05">
    <visual>
        <origin rpy="0 0 0" xyz="0 0 0.4"/>
        <geometry>
            <cylinder radius="0.15" length="0.8"/>
        </geometry>
        <material name="White"/>
    </visual>
    <collision>
        <origin rpy="0 0 0" xyz="0 0 0.4"/>
        <geometry>
            <cylinder radius="0.15" length="0.25"/>
        </geometry>
    </collision>
</link>

</robot>